<?xml version="1.0" ?>
<sdf version="1.5">
  <model name="pioneer_custom">

    <!-- Основное шасси -->
    <link name="chassis">
      <pose>0 0 0.16 0 0 0</pose>
      <inertial>
        <mass>5.67</mass>
        <inertia>
          <ixx>0.07</ixx>
          <iyy>0.08</iyy>
          <izz>0.10</izz>
        </inertia>
      </inertial>
      <collision name="collision">
        <geometry>
          <box><size>0.445 0.277 0.17</size></box>
        </geometry>
      </collision>
      <visual name="visual">
        <pose>0 0 0.04 0 0 0</pose>
        <geometry>
          <mesh>
            <uri>model://pioneer2dx/meshes/chassis.dae</uri>
          </mesh>
        </geometry>
      </visual>
    </link>

    <!-- Передний поворотный узел -->
    <link name="front_wheel_yaw">
      <pose>0.19 0 0.05 0 0 0</pose>
      <inertial><mass>0.1</mass></inertial>
    </link>

    <!-- Переднее колесо (ролик - сфера) -->
    <link name="front_wheel">
      <pose>0.19 0 0.05 0 0 0</pose>
      <inertial>
        <mass>1.0</mass>
        <inertia><ixx>0.002</ixx><iyy>0.002</iyy><izz>0.004</izz></inertia>
      </inertial>
      <collision name="collision">
        <geometry>
          <sphere><radius>0.08</radius></sphere>
        </geometry>
      </collision>
      <visual name="visual">
        <geometry>
          <sphere><radius>0.08</radius></sphere>
        </geometry>
        <material>
          <script>
            <uri>file://media/materials/scripts/gazebo.material</uri>
            <name>Gazebo/Red</name>
          </script>
        </material>
      </visual>
    </link>

    <!-- Задние колёса -->
    <link name="left_wheel">
      <pose>-0.1 0.2 0.11 0 1.5707 1.5707</pose>
      <inertial><mass>1.5</mass></inertial>
      <collision name="collision">
        <geometry>
          <cylinder><radius>0.15</radius><length>0.1</length></cylinder>
        </geometry>
      </collision>
      <visual name="visual">
        <geometry>
          <cylinder><radius>0.15</radius><length>0.1</length></cylinder>
        </geometry>
        <material>
          <script>
            <uri>file://media/materials/scripts/gazebo.material</uri>
            <name>Gazebo/Green</name>
          </script>
        </material>
      </visual>
    </link>

    <link name="right_wheel">
      <pose>-0.1 -0.2 0.11 0 1.5707 1.5707</pose>
      <inertial><mass>1.5</mass></inertial>
      <collision name="collision">
        <geometry>
          <cylinder><radius>0.15</radius><length>0.1</length></cylinder>
        </geometry>
      </collision>
      <visual name="visual">
        <geometry>
          <cylinder><radius>0.15</radius><length>0.1</length></cylinder>
        </geometry>
        <material>
          <script>
            <uri>file://media/materials/scripts/gazebo.material</uri>
            <name>Gazebo/Blue</name>
          </script>
        </material>
      </visual>
    </link>

<!-- Камера -->
<link name="camera_link">
  <pose>0.2 0 0.25 0 0 0</pose>
  <gravity>false</gravity> <!-- Отключение гравитации -->
  <sensor name="camera" type="camera">
    <camera>
      <horizontal_fov>1.047</horizontal_fov>
      <image>
        <width>640</width>
        <height>480</height>
        <format>R8G8B8</format>
      </image>
      <clip>
        <near>0.1</near>
        <far>100</far>
      </clip>
    </camera>
    <plugin name="camera_controller" filename="libgazebo_ros_camera.so">
    <cameraName>pioneer_custom/camera</cameraName>
    <imageTopicName>image_raw</imageTopicName>
    <cameraInfoTopicName>camera_info</cameraInfoTopicName>
    <frameName>camera_link</frameName>
    </plugin>
    <always_on>true</always_on>
    <update_rate>30</update_rate>
    <visualize>true</visualize>
  </sensor>
</link>

<!-- Джойнт камеры к шасси -->
<joint name="camera_joint" type="fixed">
  <parent>chassis</parent>
  <child>camera_link</child>
</joint>

    <!-- IMU -->
<link name="imu_link">
  <pose>0 0 0.2 0 0 0</pose>
  <inertial>
    <mass>0.01</mass>
    <inertia>
      <ixx>1e-6</ixx>
      <iyy>1e-6</iyy>
      <izz>1e-6</izz>
    </inertia>
  </inertial>
  <collision name="collision">
    <geometry>
      <box><size>0.01 0.01 0.01</size></box>
    </geometry>
  </collision>
  <visual name="visual">
    <geometry>
      <box><size>0.01 0.01 0.01</size></box>
    </geometry>
    <material>
      <script>
        <uri>file://media/materials/scripts/gazebo.material</uri>
        <name>Gazebo/Black</name>
      </script>
    </material>
  </visual>

  <!-- IMU sensor с ROS-плагином -->
  <sensor name="imu_sensor" type="imu">
    <always_on>true</always_on>
    <update_rate>50</update_rate>
    <imu>
      <angular_velocity>
        <x>true</x> <y>true</y> <z>true</z>
      </angular_velocity>
      <linear_acceleration>
        <x>true</x> <y>true</y> <z>true</z>
      </linear_acceleration>
    </imu>
    <plugin name="imu_plugin" filename="libgazebo_ros_imu_sensor.so">
      <ros>
        <namespace>/pioneer</namespace>
        <remapping>~/imu/data:=imu/data</remapping>
      </ros>
      <frameName>imu_link</frameName>
      <topicName>imu/data</topicName>
    </plugin>
  </sensor>
</link>

<!-- Joint для IMU -->
<joint name="imu_joint" type="fixed">
  <parent>chassis</parent>
  <child>imu_link</child>
</joint>

    <!-- Джойнты -->
    <joint type="revolute" name="left_wheel_hinge">
      <parent>chassis</parent>
      <child>left_wheel</child>
      <axis><xyz>0 1 0</xyz></axis>
    </joint>

    <joint type="revolute" name="right_wheel_hinge">
      <parent>chassis</parent>
      <child>right_wheel</child>
      <axis><xyz>0 1 0</xyz></axis>
    </joint>

    <!-- Переднее колесо: поворот (yaw) -->
    <joint type="revolute" name="front_yaw_joint">
      <parent>chassis</parent>
      <child>front_wheel_yaw</child>
      <axis><xyz>0 0 1</xyz></axis>
    </joint>

    <!-- Переднее колесо: вращение (spin) -->
    <joint type="revolute" name="front_wheel_spin">
      <parent>front_wheel_yaw</parent>
      <child>front_wheel</child>
      <axis><xyz>0 1 0</xyz></axis>
    </joint>

    <!-- Плагин дифференциального привода -->
    <plugin filename="libDiffDrivePlugin.so" name="diff_drive">
      <left_joint>left_wheel_hinge</left_joint>
      <right_joint>right_wheel_hinge</right_joint>
      <torque>5</torque>
    </plugin>

  </model>
</sdf>
